Traceback (most recent call last):
  File "/Users/skyfano/mambaforge/lib/python3.10/site-packages/pandas/core/indexes/base.py", line 3791, in get_loc
    return self._engine.get_loc(casted_key)
  File "index.pyx", line 152, in pandas._libs.index.IndexEngine.get_loc
  File "index.pyx", line 181, in pandas._libs.index.IndexEngine.get_loc
  File "pandas/_libs/hashtable_class_helper.pxi", line 7080, in pandas._libs.hashtable.PyObjectHashTable.get_item
  File "pandas/_libs/hashtable_class_helper.pxi", line 7088, in pandas._libs.hashtable.PyObjectHashTable.get_item
KeyError: 'Date'
The above exception was the direct cause of the following exception:
Traceback (most recent call last):
  File "/Users/skyfano/Documents/Masterarbeit/Prediction_of_energy_prices/predictions/LSTM_new_gen.py", line 144, in <module>
    data = load_and_prepare_data(file_path)
  File "/Users/skyfano/Documents/Masterarbeit/Prediction_of_energy_prices/predictions/LSTM_new_gen.py", line 25, in load_and_prepare_data
    df['Date'] = pd.to_datetime(df['Date'])
  File "/Users/skyfano/mambaforge/lib/python3.10/site-packages/pandas/core/frame.py", line 3893, in __getitem__
    indexer = self.columns.get_loc(key)
  File "/Users/skyfano/mambaforge/lib/python3.10/site-packages/pandas/core/indexes/base.py", line 3798, in get_loc
    raise KeyError(key) from err
KeyError: 'Date'