Traceback (most recent call last):
  File "/Users/skyfano/Documents/Masterarbeit/Prediction_of_energy_prices/predictions/LSTM_new_gen.py", line 147, in <module>
    scaler, scaled_data = scale_data(data[['Price']], 'Price')
  File "/Users/skyfano/mambaforge/lib/python3.10/site-packages/pandas/core/frame.py", line 3899, in __getitem__
    indexer = self.columns._get_indexer_strict(key, "columns")[1]
  File "/Users/skyfano/mambaforge/lib/python3.10/site-packages/pandas/core/indexes/base.py", line 6115, in _get_indexer_strict
    self._raise_if_missing(keyarr, indexer, axis_name)
  File "/Users/skyfano/mambaforge/lib/python3.10/site-packages/pandas/core/indexes/base.py", line 6176, in _raise_if_missing
    raise KeyError(f"None of [{key}] are in the [{axis_name}]")
KeyError: "None of [Index(['Price'], dtype='object')] are in the [columns]"