GpuFreq=control_disabled
[I 2024-10-08 16:17:53,465] A new study created in memory with name: no-name-8ee94286-8e87-4a72-acd3-f00f6675883c
[W 2024-10-08 16:17:53,608] Trial 0 failed with parameters: {'max_depth': 4, 'learning_rate': 0.06946976789951347, 'n_estimators': 217, 'input_chunk_length': 25, 'min_child_weight': 4.946453872541587, 'subsample': 0.89371941531932, 'colsample_bytree': 0.9317427465038852, 'gamma': 0.30844243513250036} because of the following error: TypeError("XGBModel.fit() got an unexpected keyword argument 'callbacks'").
Traceback (most recent call last):
  File "/pfs/data5/home/tu/tu_tu/tu_zxoul27/micromamba/envs/power/lib/python3.12/site-packages/optuna/study/_optimize.py", line 197, in _run_trial
    value_or_values = func(trial)
                      ^^^^^^^^^^^
  File "/pfs/data5/home/tu/tu_tu/tu_zxoul27/Prediction_of_energy_prices/predictions/XGBoost/XGBoost_cluster_2.py", line 113, in objective
    model.fit(series_train_scaled, future_covariates=future_covariates_train_scaled, verbose=False, callbacks=[early_stop])
  File "/pfs/data5/home/tu/tu_tu/tu_zxoul27/micromamba/envs/power/lib/python3.12/site-packages/darts/models/forecasting/xgboost.py", line 312, in fit
    super().fit(
  File "/pfs/data5/home/tu/tu_tu/tu_zxoul27/micromamba/envs/power/lib/python3.12/site-packages/darts/models/forecasting/regression_model.py", line 920, in fit
    self._fit_model(
  File "/pfs/data5/home/tu/tu_tu/tu_zxoul27/micromamba/envs/power/lib/python3.12/site-packages/darts/models/forecasting/regression_model.py", line 704, in _fit_model
    self.model.fit(
  File "/pfs/data5/home/tu/tu_tu/tu_zxoul27/micromamba/envs/power/lib/python3.12/site-packages/xgboost/core.py", line 726, in inner_f
    return func(**kwargs)
           ^^^^^^^^^^^^^^
TypeError: XGBModel.fit() got an unexpected keyword argument 'callbacks'
[W 2024-10-08 16:17:53,662] Trial 0 failed with value None.
Traceback (most recent call last):
  File "/pfs/data5/home/tu/tu_tu/tu_zxoul27/Prediction_of_energy_prices/predictions/XGBoost/XGBoost_cluster_2.py", line 175, in <module>
    main()
  File "/pfs/data5/home/tu/tu_tu/tu_zxoul27/Prediction_of_energy_prices/predictions/XGBoost/XGBoost_cluster_2.py", line 126, in main
    best_params = study.best_params
                  ^^^^^^^^^^^^^^^^^
  File "/pfs/data5/home/tu/tu_tu/tu_zxoul27/micromamba/envs/power/lib/python3.12/site-packages/optuna/study/study.py", line 119, in best_params
    return self.best_trial.params
           ^^^^^^^^^^^^^^^
  File "/pfs/data5/home/tu/tu_tu/tu_zxoul27/micromamba/envs/power/lib/python3.12/site-packages/optuna/study/study.py", line 162, in best_trial
    best_trial = self._storage.get_best_trial(self._study_id)
                 ^^^^^^^^^^^^^^^^^^^^^^^^^^^^^^^^^^^^^^^^^^^^
  File "/pfs/data5/home/tu/tu_tu/tu_zxoul27/micromamba/envs/power/lib/python3.12/site-packages/optuna/storages/_in_memory.py", line 232, in get_best_trial
    raise ValueError("No trials are completed yet.")
ValueError: No trials are completed yet.
srun: error: uc2n520: task 0: Exited with exit code 1
